Workbook

Sheet ENTREGAS DE CAFE
A2: PROVEEDOR:
A3: FECHA DE ENTREGA:
B6: SANTANDER | C6: MEXICO | D6: BRASIL | E6: OTRO
A7: MOLIDO
A8: GRANO
A11: PEDIDOS CAFE
A12: PROVEEDOR:
A13: FECHA DE ENTREGA:
B16: SANTANDER | C16: MEXICO | D16: BRASIL | E16: OTRO
A17: MOLIDO
A18: GRANO
A21: PEDIDOS CAFE
A22: PROVEEDOR:
A23: FECHA DE ENTREGA:
B26: SANTANDER | C26: MEXICO | D26: BRASIL | E26: OTRO
A27: MOLIDO
A28: GRANO
A31: PEDIDOS CAFE
A32: PROVEEDOR:
A33: FECHA DE ENTREGA:
B36: SANTANDER | C36: MEXICO | D36: BRASIL | E36: OTRO
A37: MOLIDO
A38: GRANO

Sheet CIERRE 2023
B1: FECHA | C1: VENTA DIARIA | D1: ZETA | E1: CAJA | F1: CAMBIO | G1: TARJETAS | H1: PEDIDOS YA PAGO-ONLINE | I1: CTA CTE | J1: MERCADO | K1: EFECTIVO DEL DIA | L1: CAJA FUERTE | M1: CAJITA
A2: LUNES | B2: 44928 | C2: 263279 | D2: 121170 | E2: =400+1000+100+240+60+1000 -> 2800 | F2: =500 -> 500 | G2: =15470+36820 -> 52290 | H2: 15790 | J2: 54440 | K2: 118169
A3: MARTES | B3: 44564 | C3: 227225 | D3: 144531 | E3: 2000 | F3: 500 | G3: =21030+29060 -> 50090 | H3: 43890 | J3: 31870 | K3: 82594
A4: MIERCOLES | B4: 44565 | C4: =244984-37200 -> 207784 | D4: 178130 | E4: 1300 | F4: 0 | G4: =27630+12950 -> 40580 | H4: 31260 | J4: 56740 | K4: 68445
A5: JUEVES | B5: 44566 | C5: 270227 | D5: 186310 | E5: =800+500+1800+520+10 -> 3630 | G5: =23710+32120 -> 55830 | H5: 54670 | J5: 41070 | K5: 84107
A6: VIERNES | B6: 44567 | C6: 236390 | D6: 155200 | E6: 2000 | F6: 0 | G6: 41020 | H6: 61930 | J6: 52810 | K6: 78150
A7: SABADO | B7: 44568 | C7: 167077 | D7: 107710 | E7: =700+1300+250+420+90 -> 2760 | F7: 2100 | G7: =41080+4400 -> 45480 | H7: 30680 | J7: 25650 | K7: 52837
A8: DOMINGO | B8: 44569
A9: LUNES | B9: 44570 | C9: 214483 | D9: 129670 | E9: =700+2800+50+400+20 -> 3970 | F9: 1300 | G9: 26020 | H9: 33080 | J9: 58660 | K9: 79693
A10: MARTES | B10: 44571 | C10: 219920 | D10: 129390 | E10: 3400 | F10: 700 | G10: 38220 | H10: 31490 | J10: 53830 | K10: 82530
A11: MIERCOLES | B11: 44572 | C11: 261475 | D11: 150760 | E11: 2200 | F11: 800 | G11: =26760+19880 -> 46640 | H11: 58060 | J11: 49770 | K11: 96685
A12: JUEVES | B12: 44573 | C12: 261596 | D12: 165032 | E12: =500+1900+50+700+60 -> 3210 | F12: 3300 | G12: =20910+34710 -> 55620 | H12: 48810 | J12: 57947 | K12: 74994
A13: VIERNES | B13: 44574 | C13: 206419 | D13: 105590 | E13: 3400 | F13: 300 | G13: =27320+2720 -> 30040 | H13: 29660 | J13: 31650 | K13: 98739
A14: SABADO | B14: 44575 | C14: 143786 | D14: 85342 | E14: 2700 | F14: 1700 | G14: =24410+7860 -> 32270 | H14: 23350 | J14: 24780 | K14: 61099
A15: DOMINGO | B15: 44576
A16: LUNES | B16: 44577 | C16: 193994 | D16: 129790 | E16: =230+50+1200+1000+800 -> 3280 | F16: =1700 -> 1700 | G16: =39420+6180 -> 45600 | H16: 39300 | J16: 27290 | K16: 69804
A17: MARTES | B17: 44578 | C17: 222688 | D17: 144939 | E17: 530 | F17: 800 | G17: =35530+5010 -> 40540 | H17: 44200 | J17: =50380+650 -> 51030 | K17: 81049
A18: MIERCOLES | B18: 44579 | C18: 200453 | D18: =116128+2900 -> 119028 | E18: 3000 | F18: 0 | G18: =1450+52010 -> 53460 | H18: 23440 | J18: 34340 | K18: 74975
A19: JUEVES | B19: 44580 | C19: 265491 | D19: 199980 | E19: 2400 | F19: 1000 | G19: 72530 | H19: 68240 | J19: 54090 | K19: 63291
A20: VIERNES | B20: 44581 | C20: 194050 | D20: 114480 | E20: 2400 | F20: 1000 | G20: =34590+5800 -> 40390 | H20: 41390 | J20: 36070 | K20: 69930
A21: SABADO | B21: 44582 | C21: =226474-39600 -> 186874 | D21: 158547 | E21: =1900+1000+250+500+210 -> 3860 | F21: 2100 | G21: =25370+8330 -> 33700 | H21: 24477 | J21: 36590 | K21: 65727
A22: DOMINGO | B22: 44583
A23: LUNES | B23: 44584 | C23: 205787 | D23: 13220 | E23: 2500 | F23: 2100 | G23: =750+7450+28410 -> 36610 | H23: 35050 | J23: 47470 | K23: 71437
A24: MARTES | B24: 44585 | C24: =175685+101448 -> 277133 | D24: 164542 | E24: =400+2100+100+80+50 -> 2730 | F24: =1000+800 -> 1800 | G24: =4400+63590 -> 67990 | H24: 30830 | J24: 56720 | K24: =43450+45018 -> 88468
A25: MIERCOLES | B25: 44586 | C25: 288807 | D25: 219649 | E25: =500+1400+2000+100+320+140 -> 4460 | F25: 200 | G25: =9400+10350+29000+26000 -> 74750 | H25: 41727 | J25: 67950 | K25: 57518
A26: JUEVES | B26: 44587 | C26: 273674 | D26: 185370 | E26: =1100+2400+50+240+120 -> 3910 | F26: 1000 | G26: =32600+9250 -> 41850 | H26: 32550 | J26: 52740 | K26: 84374
A27: VIERNES | B27: 44588 | C27: 296465 | D27: 182327 | E27: =2800+160+170 -> 3130 | F27: 500 | G27: =46970+11230 -> 58200 | H27: 38757 | J27: 45780 | K27: 103358
A28: SABADO | B28: 44589 | C28: 154742 | D28: 105487 | E28: 3600 | F28: 1900 | G28: =34910+3500 -> 38410 | H28: 27607 | J28: 28450 | K28: 46705
A29: DOMINGO | B29: 44590
A30: LUNES | B30: 44591 | C30: 235399 | D30: 152439 | E30: =2000+3300+250+720+110-900 -> 5480 | F30: =1900 -> 1900 | G30: =3100+39880 -> 42980 | H30: 44020 | J30: 61260 | K30: 78580
A31: MARTES | B31: 44592 | C31: 330134 | D31: 243732 | E31: 4100 | F31: 2100 | G31: =54780+10850 -> 65630 | H31: 69910 | J31: 78510 | K31: 83726
A32: TOTAL | B32: ENERO | C32: =SUM(C2:C31) -> 6005352 | D32: =SUM(D2:D31) -> 3792365 | G32: =SUM(G2:G31) -> 1226740 | H32: =SUM(H2:H31) -> 1024168 | J32: =SUM(J2:J31) -> 1217507 | K32: =SUM(K2:K31) -> 2016984
A34: MIERCOLES | B34: 44593 | C34: 335969 | D34: 246292 | E34: 2700 | F34: 1500 | G34: =56820+23100 -> 79920 | H34: 64817 | J34: 89050 | K34: 87609
A35: JUEVES | B35: 44594 | C35: 301366 | D35: 182630 | E35: =1200+2900+250+300+130 -> 4780 | F35: 2000 | G35: =5700+57100 -> 62800 | H35: 49870 | J35: 49760 | K35: 94376
A36: VIERNES | B36: 44595 | C36: 235122 | D36: 157367 | E36: =3500+500+100+200+50 -> 4350 | F36: =700+200+1000 -> 1900 | G36: =42500+20480 -> 62980 | H36: 27237 | J36: 40730 | K36: 75525
A37: SABADO | B37: 44596 | C37: 194718 | D37: 105130 | E37: =4580-1700 -> 2880 | F37: =2200+1000+1000+500 -> 4700 | G37: =30640+8640 -> 39280 | H37: 20780 | J37: 50478 | K37: 84798
A39: LUNES | B39: 44598 | C39: 192636 | D39: 113022 | E39: =1200+1000+800+480+120 -> 3600 | F39: 1800 | G39: =28890+5470 -> 34360 | H39: 11200 | J39: 49270 | K39: 60977
A40: MARTES | B40: 44599 | C40: 260187 | D40: 160600 | E40: 3760 | F40: 1500 | G40: 42120 | H40: 44470 | J40: 49410 | K40: 86318
A41: MIERCOLES | B41: 44600 | C41: 302785 | D41: 210680 | E41: 1350 | F41: 1500 | G41: 51110 | H41: 89527 | J41: 59710 | K41: 69105
A42: JUEVES | B42: 44601 | C42: 296810 | D42: 242895 | E42: 2100 | F42: 900 | G42: 68890 | H42: 65270 | J42: 89430 | K42: 61275
...

Sheet ENERO 2023
B1: MP | C1: CHEQUE | D1: TRANSFERENCIA | E1: ADEUDA | F1: GASTOS | H1: RETIROS
B2: 12848.82 | G2: LA SERENISIMA | H2: 102 | I2: CE
A3: LUNES 2 | F3: 1495 | G3: BRIE
F4: 3000 | G4: EVA
F5: 276 | G5: FP
B6: 25500 | G6: POLLO
B7: 10266.47 | G7: MARILU
B8: =3298*3 -> 9894 | G8: pulpa frutilla
F9: 300 | G9: moto florida
F10: 7300 | G10: huevo
F11: 421 | G11: filtro cafe
A15: MARTES 3 | C15: 51121.27 | G15: quintela | H15: 77 | I15: H
B16: 30616.38 | G16: horeca
B17: 22910.3 | G17: criollo
B18: =42480-1800 -> 40680 | G18: edu
D19: 16000 | G19: harina
D20: 8275.19 | G20: valot
F21: 2750 | G21: cucharas
D22: 19200 | G22: wraps
A28: MIERCOLES 4 | B28: 5590 | G28: tenedores | H28: 67.5 | I28: H
B29: 6545.77 | G29: la serenisima
F30: 740 | G30: folex
C31: 44931.91 | G31: ormazabal
F32: 1000 | G32: hielo
B33: 4080 | G33: choco alpino pins
B42: 25500 | G42: pollo | I42: deposite a bbva 202k y me los transferi a mi mp
C43: 25550.52 | G43: matiz | H43: 81 | I43: CE
A44: JUEVES 5 | B44: 10896.05 | G44: cuyaires
D45: 40232.5 | G45: motobaires
F46: 8000 | G46: remis marcelo
F47: 686 | G47: ferreteria
F48: 10000 | G48: Marcelo
A54: VIERNES 6 | F54: =489+239 -> 728 | G54: fp | H54: 60 | I54: H
B55: 38990 | G55: edu | H55: 5000 | I55: Retiro C
B56: 6545.77 | G56: la serenisima
B57: 12684 | G57: limpieza
B58: 64832.77 | G58: gonzanio
F59: 3000 | G59: eva
F60: 1300 | G60: moto contadora
B61: 43689.1 | G61: coca
...

Sheet FEBRERO 2023
A1: z | B1: MP | C1: CHEQUE | D1: TRANSFERENCIA | E1: ADEUDA | F1: GASTOS | H1: RETIROS
B2: 10560 | G2: wraps | H2: 77 | I2: H
A3: MIERCOLES 1 | F3: 765 | G3: fp | I3: 7606 use de mp
B4: 25500 | G4: pollo
B5: 6807.58 | G5: la serenisima
C6: 31938.65 | G6: ormazabal
C7: 36514 | G7: matiz
F8: 3715 | G8: fp
B9: 6000 | G9: frutos rojos congelados
F10: 4000 | G10: paltas
A15: JUEVES 2 | B15: 34825.75 | G15: milkaut | H15: 87 | I15: C
B16: 12060.17 | G16: marilu | I16: 21918,46 use de bbva
F17: 500 | G17: ledevit
F18: 421 | G18: filtros cafe
D19: 15673.09 | G19: colucci procesadora
F20: 2000 | G20: guantes nitrilo costa
A28: VIERNES 3 | F28: 225 | G28: rucula | H28: 42 | I28: C
F29: 430 | G29: limpieza
G30: eva
F31: 206 | G31: fp
B32: 37900 | G32: edu
C33: 38563.52 | G33: matiz
D34: 58443 | G34: motobaires
F42: 600 | G42: hielo | H42: 71 | I42: C
B43: 25500 | G43: pollo
A44: SABADO 4 | F44: 8200 | G44: huevo
A54: LUNES 6 | F54: 3800 | G54: eva | I54: C deposite 105000+19000+55500 en bbva y transf 140 a nora y 39500 a mi mp
B55: 6706.69 | G55: serenisima del viernes | H55: 55 | I55: C
F56: 902 | G56: carrefour
F57: 480 | G57: chino
F58: 314 | G58: rucula
B59: 11300 | G59: edu
C60: =25632.16+22702.02 -> 48334.18 | G60: quintela
F61: 1000 | G61: moto contadora
G62: hilo encerado
A68: MARTES 7 | B68: 3523.98 | G68: horeca | H68: 30 | I68: C
B69: 25614.21 | G69: criollo | H69: 20 | I69: retiro H :))
B70: 13878.36 | G70: marilu | H70: 32.5 | I70: Caja Roja
D71: 21742 | G71: limpieza
B72: 8263 | G72: ventilador
...

Sheet MARZO 2023
A1: z | B1: MP | C1: CHEQUE | D1: TRANSFERENCIA | E1: ADEUDA | F1: GASTOS | H1: RETIROS
C2: 39246.29 | G2: ormazabal | H2: 52.5 | I2: H
A3: MIERCOLES 1 | B3: 10396.64 | G3: la serenisima | I3: 50 transf H BBV | J3: cancelado
B4: 30000 | G4: pollo
B5: 18340 | G5: edu
B6: 28217.49 | G6: coca
A15: JUEVES 2 | B15: 56121.4 | G15: gonzanio | H15: 90 | I15: 90 H
F16: 770 | G16: etiquetas | I16: 50 Lleve
F17: 1000 | G17: hielo
B18: 8400 | G18: harina
A28: VIERNES 3 | B28: =18440-500 -> 17940 | G28: edu | H28: 31 | I28: H
B29: 11467.04 | G29: la serenisima
F30: 2000 | G30: eva
F31: 13200 | G31: aceite freidora
F32: 76 | G32: fp
F33: 606 | G33: carrefour
B34: 4538 | G34: pulpa frutilla
F35: 800 | G35: muzza
F36: 1422 | G36: limon
F42: 604 | G42: carrefour | H42: 53 | I42: C
B43: 30000 | G43: pollo
A44: SABADO 4 | C44: 14580 | G44: matiz
B45: 17457.4 | G45: milkaut
F46: 1300 | G46: BRIE
F47: 650 | G47: FRUTAS PREMIUM
A54: LUNES 6 | B54: 7779.2 | G54: la serenisima
B55: 41300 | G55: edu | H55: 73 | I55: C
C56: =42560.9+48152.74-2395.8 -> 88317.84 | G56: quintela
B57: 26695.18 | G57: marilu
F58: 648 | G58: rucula
B59: 9740.3 | G59: horeca
B60: 29620.4 | G60: criollo
B61: 36874.75 | G61: motobaires
F62: 11800 | G62: huevo
F63: 1200 | G63: brie
F64: 2000 | G64: hielo
A68: MARTES 7 | B68: 42240 | E68: pagada | G68: wraps 2 cajas | H68: 97 | I68: H
D69: 69696 | E69: pagada | G69: penguin cafe | I69: deposite 120 a bbva y me o transferi a mp
D70: 24684 | E70: pagada | G70: penguin syrup
A80: MIERCOLES 8 | B80: 30000 | G80: pollo | H80: 84 | I80: H
...

Sheet ABRIL 2023
A1: z | B1: MP | C1: CHEQUE | D1: TRANSFERENCIA | E1: ADEUDA | F1: GASTOS | H1: RETIROS
F2: =1450+1450 -> 2900 | G2: MAPLE DE HUEVO | H2: 68 | I2: C
A3: SABADO 1 | F3: 15000 | G3: HUEVO
A15: LUNES 3 | F15: 1697 | G15: brie | H15: 102 | I15: C
B16: 18002.35 | G16: la serenisima
B17: 26800 | G17: edu
B18: 27214.77 | G18: criollo
B19: 7971.11 | G19: horeca
C20: 58467.5 | G20: quintela
B21: 6174.79 | G21: tenedores
A28: MARTES 4 | F28: 300 | G28: curitas | H28: 80 | I28: H
F29: 2156 | G29: panceta | I29: transferi de Bbva a cecimp 70k
F30: 6020 | G30: pollo
F31: 45 | G31: verdeo
E32: 2798.13 | G32: quintela panceta
F33: 1200 | G33: moto
D34: 60592.32 | G34: marilu
F35: 5000 | G35: eva
B36: 2120 | G36: wraps
B37: 4552 | G37: leche carrefour
F38: 15000 | G38: huevo
B39: =1875+1917 -> 3792 | G39: crema
B40: 3977 | G40: cajas breik
B42: 51350 | G42: edu | H42: 97 | I42: H
B43: 15414.46 | G43: la serenisima
A44: MIERCOLES 5 | B44: 10880 | G44: valot
B45: 36487.8 | G45: marilu
D46: 52450 | G46: laurimar
D47: 65340 | E47: pagado | G47: penguin
D48: 53920.63 | G48: motobaires
B49: 25677 | G49: milkaut
B50: 9600 | G50: feras
C51: 50736.43 | G51: ormazabal
F52: 2300 | G52: ormazabal
A54: JUEVES 6 | B54: 20520.92 | G54: la serenisima | H54: 90 | I54: C
B55: 15960 | G55: harina
C56: 64051 | G56: matiz
D57: 52282.26 | G57: coca_Femsa
B58: 31000 | G58: manteca
A68: VIERNES 7 | H68: 74 | I68: C
...

Sheet MAYO 2023
A1: z | B1: MP | C1: CHEQUE | D1: TRANSFERENCIA | E1: ADEUDA | F1: GASTOS | H1: RETIROS
F2: 1219 | G2: LIMPIEZA CARREFOUR | I2: repuse 94000 en ef porque use de bbva
A3: MARTES 2 | F3: 1792 | G3: FP | H3: 80 | I3: H
B4: 31000 | G4: MANTECA
B5: 32805.2 | G5: MARILU
F6: 5200 | G6: eva
F7: 10000 | G7: marcelo
F8: =2400+2730 -> 5130 | G8: repuestos marcelo
C9: =43784.52 -> 43784.52 | G9: quintela
A15: MIERCOLES 3 | B15: 9933.5 | G15: la serenisima | I15: 50k transferi de bbva a cecimp
B16: 40550 | G16: edu | H16: 100 | I16: H
B17: 26759.58 | G17: criollo
B18: 2812.95 | G18: horeca
C19: 13105.92 | G19: ormazabal
D20: 56510 | G20: motobaires
F21: 52500 | G21: mercou
B22: 1633 | G22: uber contadora
B23: 1118 | G23: arroz
A28: JUEVES 4 | D28: 49549.5 | E28: pagada | G28: penguin | H28: 108 | I28: C
C29: 10329.08 | G29: criollo
C30: 15389.06 | G30: horeca
B42: 32050 | G42: edu | H42: 75.5 | I42: H
B43: 4966.75 | G43: la serenisima
A44: VIERNES 5 | F44: 5800 | G44: EVA
F45: 3600 | G45: Chino
A54: SABADO 6 | F54: 6500 | G54: 2 dias prueba jm | H54: 80 | I54: H
B55: 4231.5 | G55: brie
A68: LUNES 8 | C68: =69472.22 -> 69472.22 | G68: quintela | H68: 70 | I68: H
B69: 9933.5 | G69: la serenisima
B70: 23550 | G70: edu
B71: 54000 | G71: pollo
B72: 36108.72 | G72: marilu
C73: 47206.7 | G73: matiz
F74: 1000 | G74: hielo
A80: MARTES 9 | F80: 5200 | G80: eva | I80: deposite en bbva 220 y me lo transferi a cecimp
B81: 31000 | G81: manteca | H81: 100 | I81: H
B82: 6871.36 | G82: horeca
B83: 24517.17 | G83: criollo
B84: 12888 | G84: pulpa frutilla
B85: 2348 | G85: sorbetes compostables
...

Sheet JUNIO 2023
A1: z | B1: MP | C1: CHEQUE | D1: TRANSFERENCIA | E1: ADEUDA | F1: GASTOS EN EFT | H1: RETIROS
F2: 567 | G2: albahaca | H2: 120 | I2: H
B3: 30580 | G3: harina
A4: JUE 1 | D4: 56567,5 | E4: pagada | G4: penguin
C5: 56017,55 | G5: matiz
A15: VIERNES 2 | B15: 18674,44 | G15: la serenisima
B16: 30400 | G16: edu
D17: 12523,72 | G17: marilu
B18: 52332,42 | G18: coca
F19: 7000 | G19: eva
B20: 7720 | G20: eva
A28: SABADO 3 | B28: 48000 | G28: pollo | H28: 66 | I28: C | J28: Que paso aca?
B29: 44683.02 | G29: milkaut
F30: 2400 | G30: horas extra carla
F31: 15000 | G31: huevo
B42: 37000 | G42: manteca | H42: 98 | I42: H
B43: 22950 | G43: edu
A44: LUNES 5 | B44: 10926.68 | G44: la serenisima
D45: 100000 | G45: Laurimar
F46: 2200 | G46: azucar
C47: =63761.74+23173.92-6352.5 -> 80583.16 | G47: quintela
F48: 1200 | G48: durazno
A54: MARTES 6 | D54: 50173.35 | G54: criollo | H54: 100 | I54: H
D55: 8264.99 | G55: horeca | I55: c uso del bbva (84037,22+9800) se repone depositamdo el ef en la cuenta, mañana miercoles
B56: 36917.23 | G56: marilu | I56: deposite 310000 y me transferi 216162,78, quedo todo cancelado en 0
B57: 18411.86 | G57: cuyaires
B58: 29750.06 | G58: harina
F59: 1200 | G59: farmacia
D60: 57814.1 | E60: si | G60: baires moto
F61: 645 | G61: limpieza
B62: 8828.8 | G62: colorantes
B63: 8735 | G63: breik
B64: 12800 | G64: frutos rojos
F65: 1332 | G65: leche
A68: MIERCOLES 7 | C68: 42237.7 | G68: ormazabal | H68: 90 | I68: H
B69: 5463.34 | G69: la serenisima
B70: 12600 | G70: edu
F71: 2785 | G71: leche
A80: JUEVES 8 | B80: 48000 | G80: pollo | H80: 100 | I80: H
D81: 86636 | E81: pagado | G81: penguin
...

Sheet JULIO 2023
A1: z | B1: MP | C1: CHEQUE | D1: TRANSFERENCIA | E1: ADEUDA | F1: GASTOS EN EFT | H1: RETIROS
F2: 15000 | G2: ag leo | H2: 94 | I2: C
A3: SABADO 1
A15: LUNES 3 | I15: deposite en Bbva 201 mio y lo tr a cecimp
F16: 4950 | G16: dai limpieza | H16: 84 | I16: C
B17: 14053.3 | G17: la serenisima
B18: 39500 | G18: edu
C19: 61196.96 | G19: quintela
F20: 15000 | G20: huevo
B21: 8162.4 | G21: pulpa frutilla
B22: 7242 | G22: tenedor descartable
A28: MARTES 4 | B28: 26840 | G28: wraps | H28: 83 | I28: C
B29: 40700 | G29: manteca
C30: 51340.29 | G30: matiz
D31: 26130.97 | G31: criollo
D32: 15825.99 | G32: horeca
B33: 1436.5 | G33: restante feras
D34: 53043.07 | G34: motobaires
D35: 22680 | E35: pagado | G35: Penguin
B42: 11664.79 | G42: la serenisima | H42: 105 | I42: C
B43: 13550 | G43: edu
A44: MIERCOLES 5 | D44: 48000 | G44: pollo
C45: 63044.63 | G45: ormazabal
B46: 20816.23 | G46: milkaut
F47: 4400 | G47: sole limpieza
F48: 15800 | G48: ACEITE freidora
F49: 18000 | G49: conducto fabricio
F50: 10000 | G50: puso H conducto fabricio, compensado
A54: JUEVES 6 | B54: 21000 | G54: HARINA | H54: 90 | I54: H
D55: 30800 | G55: DISTRI LIMPIEZA
D56: 26559.84 | G56: CUYAIRES
D57: 37966.78 | G57: MARILU
F58: 16300 | G58: ACEITE OLIVA PANES
F59: 2767 | G59: nuevo emporio
F60: 3000 | G60: electricidasd
A68: VIERNES 7 | B68: 16108.31 | G68: la serenisima | H68: 90 | I68: H
B69: 20750 | G69: edu
B70: 46135.77 | G70: coca
A80: SABADO 8 | B80: 12925.4 | G80: queso brie y crudo | H80: 120 | I80: H
C81: =49543.45+52593.8 -> 102137.25 | G81: quintela
...

Sheet AGOSTO 2023
A1: z | B1: MP | C1: CHEQUE | D1: TRANSFERENCIA | E1: ADEUDA | F1: GASTOS EN EFT | H1: RETIROS
F2: 840 | G2: chorizo | H2: 140 | I2: H
A3: MARTES 1 | D3: 36647.12 | E3: pagado | G3: valot
B4: 32057.59 | G4: criollo
B5: 22361.88 | G5: horeca
B6: 14100 | G6: tacos
B7: 18000 | G7: cartas
G8: matiz? | I8: C uso 77898 de Bbva repone en efectivo
G9: dia amira
A15: MIERCOLES 2 | B15: 12509.04 | G15: la serenisima | H15: 140 | I15: H
D16: 51000 | G16: pollo
C17: 41552.38 | G17: ormazabal
B18: 40700 | G18: manteca
D19: 68340 | G19: distri LJ limpieza
B20: 43550 | G20: edu
F21: 17000 | G21: huevo
F22: 6250 | G22: rodri
A28: JUEVES 3 | B28: 20800 | G28: harina | H28: 121 | I28: H
F29: 2600 | G29: hielo
B42: 26700 | G42: edu | H42: 152 | I42: C
B43: 18763.57 | G43: la serenisima
A44: VIERNES 4 | D44: 73463.5 | G44: motobaires
B45: 23132 | G45: harina de almendras y colorante
B46: 4800 | G46: yogur y vegetalina
A54: SABADO 5 | B54: 47519.62 | G54: milkaut | H54: 81 | I54: C
C55: =76748.42+43926.63 -> 120675.05 | G55: quintela
F56: 3800 | G56: leche
A68: LUNES 7 | B68: 35000 | G68: escribania poder (pague yo en ef y me lo transferi en mp)
B69: 51000 | G69: pollo | H69: 84 | I69: H
B70: =31150-15500 -> 15650 | G70: edu | I70: deposite 230k en Bbva y me lo transferi a mp
F71: 5600 | G71: dai limpieza
F72: 526 | G72: carrefour ricota
B73: 29209 | G73: la serenisima
B74: 50642.61 | G74: marilu
F75: 17000 | G75: huevo
D76: 87021 | G76: honorarios abogada
B77: 31000 | G77: choco alpino pins
B78: 10425 | G78: pulpa de frutilla
A80: MARTES 8 | B80: 10795 | G80: certfic control fiscal key digital
F81: 1620 | G81: moto contadora
...

Sheet CIERRE 2024
A1: < | B1: FECHA | C1: VENTA DIARIA | D1: ZETA | E1: CAJA | F1: CAMBIO | G1: TARJETAS | H1: PEDIDOS YA PAGO-ONLINE | I1: CTA CTE | J1: MERCADO | K1: EFECTIVO DEL DIA | L1: CAJA FUERTE | M1: CAJITA
A2: LUNES | B2: 45292
A3: MARTES | B3: 45293 | C3: 566040 | D3: 358700 | E3: 3900 | F3: 7500 | G3: =8400+186800 -> 195200 | H3: 132856 | I3: 33700 | J3: 61300 | K3: 163640
A4: MIERCOLES | B4: 45294 | C4: 531340 | D4: 408580 | E4: 3900 | F4: 10400 | G4: =135000+7000 -> 142000 | H4: 152707 | J4: 122080 | K4: 124160
A5: JUEVES | B5: 45295 | C5: =1193100-396200 -> 796900 | D5: 549460 | E5: =600+1500+2200+250+500+800+240 -> 6090 | F5: =10400 -> 10400 | G5: =9500+247550 -> 257050 | H5: 129775 | I5: =465500-396200 -> 69300 | J5: 149610 | K5: 187490
A6: VIERNES | B6: 45296 | C6: =1639650-796900-396200 -> 446550 | D6: 296500 | E6: 7800 | F6: 10300 | G6: 179800 | H6: 92371 | I6: 31400 | J6: =212610-J5 -> 63000 | K6: =249340-K5 -> 61850
A7: SABADO | B7: 45297 | C7: 511010 | D7: 414500 | E7: =700+2100+500+500+800+280 -> 4880 | F7: 4400 | G7: =238000+24700 -> 262700 | H7: 69621 | J7: 95700 | K7: 85110
A8: DOMINGO
A9: LUNES | B9: 45299 | C9: 500720 | D9: 350950 | E9: 4800 | F9: 4400 | G9: 155100 | H9: 69936 | J9: 116800 | K9: 155370
A10: MARTES | B10: 45300 | C10: 527390 | D10: 368840 | E10: =1000+400+750+500+840+240 -> 3730 | F10: =4400 -> 4400 | G10: =123810+6200 -> 130010 | H10: 173866.5 | J10: 62600 | K10: 157750
A11: MIERCOLES | B11: 45301 | C11: 670100 | D11: 495650 | E11: =2000+1000+1200+300+500+840+250 -> 6090 | F11: 4400 | G11: =211000+23700 -> 234700 | H11: 111871 | I11: 26800 | J11: 132200 | K11: 148750
A12: JUEVES | B12: 45302 | C12: 732930 | D12: 647150 | E12: =800+2500+700+550+500+880+220 -> 6150 | F12: =4400 -> 4400 | G12: =162600+106000 -> 268600 | H12: 207310.5 | J12: 138700 | K12: 94280
A13: VIERNES | B13: 45303 | C13: 549550 | D13: 450950 | E13: 1000 | F13: 4400 | G13: =228270+6800 -> 235070 | H13: 86871 | J13: 131000 | K13: 98600
A14: SABADO | B14: 45304 | C14: 548110 | D14: 456960 | E14: 1800 | F14: 2400 | G14: =218760+69900 -> 288660 | H14: 88886 | J14: 79500 | K14: 91150
A15: DOMINGO
A16: LUNES | B16: 45306 | C16: 630080 | D16: 480860 | E16: 3500 | F16: 1400 | G16: =200500+49300+11400 -> 261200 | H16: 95947 | I16: 24200 | J16: 131960 | K16: 124120
A17: MARTES | B17: 45307 | C17: 549500 | D17: 438150 | E17: 5300 | F17: 4400 | G17: =212000+6500 -> 218500 | H17: 115901 | J17: 92750 | K17: 122350
A18: MIERCOLES | B18: 45308 | C18: 714720 | D18: 568600 | E18: 4500 | F18: 7400 | G18: =174600+65400 -> 240000 | H18: 156310 | J18: 139000 | K18: 130220
A19: JUEVES | B19: 45309 | C19: 750160 | D19: 592160 | E19: =1200+1200+900+500+820+250 -> 4870 | F19: 7400 | G19: =11000+248500 -> 259500 | H19: 195000 | I19: 24700 | J19: 154160 | K19: 138900
A20: VIERNES | B20: 45310 | C20: 606205 | D20: 479460 | E20: =1000+1400+950+500+800+250 -> 4900 | F20: 10400 | G20: =5200+261400 -> 266600 | H20: 92811 | J20: 89960 | K20: 126745
A21: SABADO | B21: 45311 | C21: 432800 | D21: 270730 | E21: =1000+900+900+500+820+240 -> 4360 | F21: 6400 | G21: =159500+3000 -> 162500 | H21: 60951 | J21: 58130 | K21: 159970
A22: DOMINGO
A23: LUNES | B23: 45313 | C23: 447650 | D23: 287450 | E23: 8000 | F23: 14400 | G23: 166100 | H23: 38980 | J23: 105200 | K23: 145700
A24: MARTES | B24: 45314 | C24: 776700 | D24: 619600 | E24: 5000 | F24: 4400 | G24: =159000+71000 -> 230000 | H24: 202181 | J24: 167900 | K24: 166200
A25: MIERCOLES | B25: 45315 | C25: 507630 | D25: 396210 | G25: 83350 | H25: 83510 | J25: 95800 | K25: 127480
A26: JUEVES | B26: 45316 | C26: =831440-210100 -> 621340 | D26: 689410 | G26: 119200 | H26: 102901 | J26: 76600 | K26: 139630
A27: VIERNES | B27: 45317 | C27: 552470 | D27: 431850 | E27: 6500 | F27: 6600 | G27: =190100+14000 -> 204100 | H27: 125551 | J27: 140200 | K27: 124920
A28: SABADO | B28: 45318 | C28: 446070 | D28: 322740 | E28: 4500 | F28: 6500 | G28: 144340 | H28: 97156 | J28: 76600 | K28: 128730
A29: DOMINGO
A30: LUNES | B30: 45320 | C30: 604740 | D30: 431040 | E30: 2600 | F30: =1600+3000+2000 -> 6600 | G30: =192800+1100 -> 193900 | H30: 127400 | J30: 118700 | K30: 160100
A31: Martes | B31: 45321 | C31: 495230 | D31: 386430 | E31: =500+1900+750+200+160+300 -> 3810 | F31: 4600 | G31: =6500+187030 -> 193530 | H31: 77500 | J31: 142100 | K31: 87000
A32: Miercoles | B32: 45322 | C32: 518050 | D32: 423980 | E32: 3200 | F32: 4600 | G32: 155400 | H32: 115510 | J32: 184680 | K32: 70770
A33: TOTAL | C33: =SUM(C2:C32) -> 15033985
A34: JUEVES | B34: 45323 | C34: 552340 | D34: 441800 | F34: 3600 | G34: 229500 | H34: 94400 | J34: 123900 | K34: 81540
A35: VIERNES | B35: 45324 | C35: 552810 | D35: 383410 | F35: 11600 | G35: 123600 | H35: 92456 | J35: 134210 | K35: 165400
A36: SABADO | B36: 45325 | C36: 432660 | D36: 344900 | E36: =1500+1500+700+400+310 -> 4410 | F36: =2000+1000+6000 -> 9000 | G36: =14900+223100 -> 238000 | H36: 36600 | J36: 56600 | K36: 87760
A37: DOMINGO
A38: LUNES | B38: 45327 | C38: 649730 | D38: 501120 | E38: 3000 | F38: 7500 | G38: 233740 | H38: 137261 | J38: 118500 | K38: 168390
A39: MARTES | B39: 45328 | C39: 659570 | D39: 478990 | E39: 3000 | F39: 3500 | G39: 230810 | H39: 135871 | J39: 128880 | K39: 168080
A40: MIERCOLES | B40: 45329 | C40: 710220 | D40: 526620 | E40: 3500 | F40: 3500 | G40: =250570+21600 -> 272170 | H40: 138610 | J40: 118700 | K40: 189200
...

Sheet CIERRE 2025
A1: < | B1: FECHA | C1: VENTA DIARIA | D1: ZETA | E1: CAJA | F1: CAMBIO | G1: TARJETAS | H1: RAPPI PAGO-ONLINE | I1: PEDIDOSYA PAGO-ONLINE | J1: CTA CTE | K1: MERCADO | L1: EFECTIVO DEL DIA | M1: RETIROS | N1: CAJA
A2: LUNES | B2: 45292
A3: MARTES | B3: 45293 | C3: 566040 | D3: 358700 | E3: 3900 | F3: 7500 | G3: =8400+186800 -> 195200 | H3: 132856 | J3: 33700 | K3: 61300 | L3: 163640
A4: MIERCOLES | B4: 45294 | C4: 531340 | D4: 408580 | E4: 3900 | F4: 10400 | G4: =135000+7000 -> 142000 | H4: 152707 | K4: 122080 | L4: 124160
A5: JUEVES | B5: 45295 | C5: =1193100-396200 -> 796900 | D5: 549460 | E5: =600+1500+2200+250+500+800+240 -> 6090 | F5: =10400 -> 10400 | G5: =9500+247550 -> 257050 | H5: 129775 | J5: =465500-396200 -> 69300 | K5: 149610 | L5: 187490
A6: VIERNES | B6: 45296 | C6: =1639650-796900-396200 -> 446550 | D6: 296500 | E6: 7800 | F6: 10300 | G6: 179800 | H6: 92371 | J6: 31400 | K6: =212610-K5 -> 63000 | L6: =249340-L5 -> 61850
A7: SABADO | B7: 45297 | C7: 511010 | D7: 414500 | E7: =700+2100+500+500+800+280 -> 4880 | F7: 4400 | G7: =238000+24700 -> 262700 | H7: 69621 | K7: 95700 | L7: 85110
A8: DOMINGO
A9: LUNES | B9: 45299 | C9: 500720 | D9: 350950 | E9: 4800 | F9: 4400 | G9: 155100 | H9: 69936 | K9: 116800 | L9: 155370
A10: MARTES | B10: 45300 | C10: 527390 | D10: 368840 | E10: =1000+400+750+500+840+240 -> 3730 | F10: =4400 -> 4400 | G10: =123810+6200 -> 130010 | H10: 173866.5 | K10: 62600 | L10: 157750
A11: MIERCOLES | B11: 45301 | C11: 670100 | D11: 495650 | E11: =2000+1000+1200+300+500+840+250 -> 6090 | F11: 4400 | G11: =211000+23700 -> 234700 | H11: 111871 | J11: 26800 | K11: 132200 | L11: 148750
A12: JUEVES | B12: 45302 | C12: 732930 | D12: 647150 | E12: =800+2500+700+550+500+880+220 -> 6150 | F12: =4400 -> 4400 | G12: =162600+106000 -> 268600 | H12: 207310.5 | K12: 138700 | L12: 94280
A13: VIERNES | B13: 45303 | C13: 549550 | D13: 450950 | E13: 1000 | F13: 4400 | G13: =228270+6800 -> 235070 | H13: 86871 | K13: 131000 | L13: 98600
A14: SABADO | B14: 45304 | C14: 548110 | D14: 456960 | E14: 1800 | F14: 2400 | G14: =218760+69900 -> 288660 | H14: 88886 | K14: 79500 | L14: 91150
A15: DOMINGO
A16: LUNES | B16: 45306 | C16: 630080 | D16: 480860 | E16: 3500 | F16: 1400 | G16: =200500+49300+11400 -> 261200 | H16: 95947 | J16: 24200 | K16: 131960 | L16: 124120
A17: MARTES | B17: 45307 | C17: 549500 | D17: 438150 | E17: 5300 | F17: 4400 | G17: =212000+6500 -> 218500 | H17: 115901 | K17: 92750 | L17: 122350
A18: MIERCOLES | B18: 45308 | C18: 714720 | D18: 568600 | E18: 4500 | F18: 7400 | G18: =174600+65400 -> 240000 | H18: 156310 | K18: 139000 | L18: 130220
A19: JUEVES | B19: 45309 | C19: 750160 | D19: 592160 | E19: =1200+1200+900+500+820+250 -> 4870 | F19: 7400 | G19: =11000+248500 -> 259500 | H19: 195000 | J19: 24700 | K19: 154160 | L19: 138900
A20: VIERNES | B20: 45310 | C20: 606205 | D20: 479460 | E20: =1000+1400+950+500+800+250 -> 4900 | F20: 10400 | G20: =5200+261400 -> 266600 | H20: 92811 | K20: 89960 | L20: 126745
A21: SABADO | B21: 45311 | C21: 432800 | D21: 270730 | E21: =1000+900+900+500+820+240 -> 4360 | F21: 6400 | G21: =159500+3000 -> 162500 | H21: 60951 | K21: 58130 | L21: 159970
A22: DOMINGO
A23: LUNES | B23: 45313 | C23: 447650 | D23: 287450 | E23: 8000 | F23: 14400 | G23: 166100 | H23: 38980 | K23: 105200 | L23: 145700
A24: MARTES | B24: 45314 | C24: 776700 | D24: 619600 | E24: 5000 | F24: 4400 | G24: =159000+71000 -> 230000 | H24: 202181 | K24: 167900 | L24: 166200
A25: MIERCOLES | B25: 45315 | C25: 507630 | D25: 396210 | G25: 83350 | H25: 83510 | K25: 95800 | L25: 127480
A26: JUEVES | B26: 45316 | C26: =831440-210100 -> 621340 | D26: 689410 | G26: 119200 | H26: 102901 | K26: 76600 | L26: 139630
A27: VIERNES | B27: 45317 | C27: 552470 | D27: 431850 | E27: 6500 | F27: 6600 | G27: =190100+14000 -> 204100 | H27: 125551 | K27: 140200 | L27: 124920
A28: SABADO | B28: 45318 | C28: 446070 | D28: 322740 | E28: 4500 | F28: 6500 | G28: 144340 | H28: 97156 | K28: 76600 | L28: 128730
A29: DOMINGO
A30: LUNES | B30: 45320 | C30: 604740 | D30: 431040 | E30: 2600 | F30: =1600+3000+2000 -> 6600 | G30: =192800+1100 -> 193900 | H30: 127400 | K30: 118700 | L30: 160100
A31: Martes | B31: 45321 | C31: 495230 | D31: 386430 | E31: =500+1900+750+200+160+300 -> 3810 | F31: 4600 | G31: =6500+187030 -> 193530 | H31: 77500 | K31: 142100 | L31: 87000
A32: Miercoles | B32: 45322 | C32: 518050 | D32: 423980 | E32: 3200 | F32: 4600 | G32: 155400 | H32: 115510 | K32: 184680 | L32: 70770
A33: TOTAL | C33: =SUM(C2:C32) -> 15033985
A34: JUEVES | B34: 45323 | C34: 552340 | D34: 441800 | F34: 3600 | G34: 229500 | H34: 94400 | K34: 123900 | L34: 81540
A35: VIERNES | B35: 45324 | C35: 552810 | D35: 383410 | F35: 11600 | G35: 123600 | H35: 92456 | K35: 134210 | L35: 165400
A36: SABADO | B36: 45325 | C36: 432660 | D36: 344900 | E36: =1500+1500+700+400+310 -> 4410 | F36: =2000+1000+6000 -> 9000 | G36: =14900+223100 -> 238000 | H36: 36600 | K36: 56600 | L36: 87760
A37: DOMINGO
A38: LUNES | B38: 45327 | C38: 649730 | D38: 501120 | E38: 3000 | F38: 7500 | G38: 233740 | H38: 137261 | K38: 118500 | L38: 168390
A39: MARTES | B39: 45328 | C39: 659570 | D39: 478990 | E39: 3000 | F39: 3500 | G39: 230810 | H39: 135871 | K39: 128880 | L39: 168080
A40: MIERCOLES | B40: 45329 | C40: 710220 | D40: 526620 | E40: 3500 | F40: 3500 | G40: =250570+21600 -> 272170 | H40: 138610 | K40: 118700 | L40: 189200
...

Sheet Hoja 11
B3: LUNES | C3: MARTES | D3: MIERCOLES | E3: JUEVES | F3: VIERNES | G3: SABADO | H3: DOMINGO
A4: TURNO | E4: JUAN | F4: JUAN | G4: JUAN
A5: MAÑANA | B5: JUAN SOLO | C5: JUAN SOLO | D5: JUAN SOLO
A6: 8 A 14 HS | E6: PRIS | F6: PRIS | G6: PRIS
C7: S
A8: TURNO | B8: AGUS | C8: AGUS | D8: AGUS | E8: AGUS | F8: AGUS | G8: AGUS
A9: TARDE
A10: 14 A 20 HS | B10: SEBA | C10: PRIS | D10: SEBA | E10: SEBA | F10: SEBA | G10: SEBA
A11: FRANCOS | B11: SEBA | C11: SEBA | D11: SEBA | E11: SEBA | F11: SEBA | G11: SEBA | H11: AGUS

Sheet SEPTIEMBRE 2023
A1: z | B1: MP | C1: CHEQUE | D1: TRANSFERENCIA | E1: ADEUDA | F1: GASTOS EN EFT | H1: RETIROS
F2: =3888+2268 -> 6156 | G2: leche carrefour | H2: 120 | I2: H
A3: VIERNES 1 | F3: 5600 | G3: dai limpieza
B4: 18350 | G4: edu
B5: 18500 | G5: syrups
F6: 1500 | G6: moto syrups
D7: 76865.25 | G7: motobaires
B8: 200000 | G8: laurimar
A15: SABADO 2 | B15: 21075.7 | G15: brie | H15: 85 | I15: H
B16: 19701.7 | G16: la serenisima | I16: 250 se transf de bbva a h
B17: 45984.22 | G17: milkaut | I17: 250 se transf de bbva a C (94656 pague comafi de bbva y 155344 a mi mp)
F18: 23500 | G18: huevo
A28: LUNES 4 | B28: 51917.47 | G28: la serenisima | H28: 90 | I28: H
B29: 45600 | G29: edu
F30: 2270 | G30: carrefour
C31: =46212.86+69735.93 -> 115948.79 | G31: quintela
D32: 55903.55 | G32: marilu
F33: 5600 | G33: dai limpieza
D42: 66000 | G42: pollo | H42: 133 | I42: H
D43: 50000 | G43: manteca
A44: MARTES 5 | D44: =24257.9+18540.68 -> 42798.58 | G44: criollo
D45: 4116.53 | G45: horeca
D46: 22641.45 | G46: feras
F47: 10000 | G47: enchife cafetera
F48: 1600 | G48: moto contadora
A54: MIERCOLES 6 | F54: 5600 | G54: sole limpieza | H54: 123 | I54: H
F55: 869 | G55: prod limpieza
B56: 20900 | G56: edu
C57: 41066.61 | G57: ormazabal
D58: 108262.33 | G58: gonzanio
A68: JUEVES 7 | F68: 2000 | G68: hielo | H68: 180 | I68: H
B69: 32670 | G69: harina
D70: 79217.8 | G70: cuyaires
C71: 71385.2 | G71: matiz
B72: 20449 | G72: wraps
B73: 40898 | G73: wraps
A80: VIERNES 8 | B80: 40850 | G80: edu
B81: 26268.94 | G81: la serenisima
F82: 5600 | G82: dai limpieza
B83: 45591.93 | G83: coca femsa
...

Sheet OCTUBRE 2023
A1: z | B1: MP | C1: CHEQUE | D1: TRANSFERENCIA | E1: ADEUDA | F1: GASTOS EN EFT | H1: RETIROS
F2: 23500 | G2: huevo | H2: 78.5 | I2: H
A3: LUNES 2 | F3: 5600 | G3: dai limpieza
B4: 49500 | G4: Edu
B5: 29967.45 | G5: la serenisima
D6: 52871.92 | G6: marilu
F7: 1160 | G7: ricota
B8: 25306.93 | G8: criollo
B9: 199254.71 | G9: horeca | I9: tenia a favor 13k
A15: MARTES 3 | D15: 58000 | G15: manteca | H15: 131.5 | I15: H
B16: 20442.5 | G16: feras f rojos
D17: 25306.93 | E17: si | G17: criollo
D18: 19254.71 | E18: si | G18: horeca
A28: MIERCOLES 4 | C28: 79121.56 | G28: ormazabal | H28: 130
F29: 5000 | G29: Milo
B30: 27423.44 | G30: la serenisima
D31: 20449 | G31: wraps
G32: sole limpieza ?
B33: 45250 | G33: edu
B42: 23200 | G42: aceite freidora | H42: =85.5-55 -> 30.5
B43: 66000 | G43: pollo
A44: JUEVES 5 | B44: 12716 | G44: pulpa frutilla
C45: 55417.75 | G45: matiz
G46: penguin
B47: 84267.69 | G47: femsa coca
B48: 46980 | G48: cajon de dinero
A54: VIERNES 6 | B54: =26700-1600 -> 25100 | G54: edu | H54: 134.5 | I54: H
B55: 20686.92 | G55: la serenisima
F56: 4900 | G56: dai
D58: 77591.25 | G58: motobaires
F59: 1930 | G59: banana
F60: 3000 | G60: hielo
A68: SABADO 7 | F68: 23500 | G68: huevo | H68: 95
F69: 1055 | G69: coliflor
C70: =83836.67+53160.68 -> 136997.35 | G70: quintela
A80: LUNES 9 | B80: =60200-25000 -> 35200 | G80: edu | H80: 80
F81: 1542 | G81: frutas premium
B82: 33106.98 | G82: la serenisima
F83: 5600 | G83: dai
D84: 49644.39 | G84: marilu
...

Sheet NOVIEMBRE 2023
A1: 7 | B1: MP | C1: CHEQUE | D1: TRANSFERENCIA | E1: ADEUDA | F1: GASTOS EN EFT | H1: RETIROS
F2: 7400 | G2: SOLE limpieza | H2: 164 | I2: H
A3: MIERC 1 | B3: 32400 | G3: edu
B4: 20604.17 | G4: la serenisima
C5: 41283.46 | G5: ormazabal
D6: 54585.87 | G6: valot
B7: 160083 | G7: motofeca
A15: JUE 2 | F15: =970+890 -> 1860 | G15: fp | H15: =90+34 -> 124
B16: 39450 | G16: harina del rosario
A28: VIE 3 | F28: 7400 | G28: dai limp | H28: 120
B29: 10200 | G29: edu
B30: 15204.8 | G30: la serenisima
C31: 99641.75 | G31: matiz
D32: 107145.5 | G32: baires
B42: 6295.7 | G42: BRIE | H42: 120
B43: 50667.98 | G43: milkaut
A44: SAB 4 | D44: 65138.4 | G44: marilu
B45: 75000 | G45: pollo
B46: 23500 | G46: huevo
C47: =102873.6+50933.74 -> 153807.34 | G47: quintela
D48: 170000 | G48: laurimar
A54: LU 6 | F54: 7400 | G54: dai limpieza | H54: 130
B55: 15204.8 | G55: la serenisima
B56: 69500 | G56: edu
B57: 25400 | G57: alpino pins bco
A68: MA 7 | F68: 2839 | G68: moto contadora | H68: 127 | I68: C
B69: 23667 | G69: pulpa frutilla
B70: 9943 | G70: choco alp negro
F71: 10800 | G71: fumigador
A80: MIE 8 | B80: 58000 | G80: manteca | H80: 148.5
B81: 27900 | G81: edu
B82: 15204.8 | G82: la serenisima
C83: 157235.49 | G83: ormzabal
F84: 916 | G84: yogur
F85: 3600 | G85: hielo
F86: 29925 | G86: wraps
D87: 213444 | E87: pagado | G87: motofeca
B88: 19320 | G88: colorantes
A96: JUE 9 | F96: 813 | G96: fp | H96: 106
B97: 18000 | G97: harina | I97: adelante 10000 a cecimp
...

Sheet DICIEMBRE 2023
B1: MP | C1: CHEQUE | D1: TRANSFERENCIA | E1: ADEUDA | F1: GASTOS EN EFT | H1: RETIROS
C2: 69428 | G2: matiz | H2: =70-60+40+16.5 -> 66.5 | I2: -mARY
A3: VIE 1 | B3: 17880.67 | G3: la serenisima
F4: 7400 | G4: dai
A15: SAB 2 | F15: 3596 | G15: fp palta | H15: 78.5
B16: 37947.92 | G16: milkaut
G17: transferi mio a bbva 162 (con eso pague comafi 131)
G18: y 30625,67 transferi a mi mp
A28: LU 4 | D28: 78000 | E28: pagado | G28: pollo | H28: 162
B29: 35555.02 | G29: la serenisima
B30: 24000 | E30: pagado | G30: huev0
B31: 88200 | E31: pagado | G31: edu
C32: =94409.04+99620.51 -> 194029.55 | G32: quintela
F33: 7400 | G33: dai limpieza
D34: 100000 | G34: laurimar
B35: 28645 | G35: choco alpino bco
G36: transferi a bbva 120000 mio y lo pase a cecimp
C42: 74152.05 | G42: ORMAZABAL | H42: 190
F43: 654 | G43: carrefour
A44: MA 5 | D44: 41624 | G44: wraps
A54: MIE 6 | F54: 5550 | G54: sole | H54: 110
B55: 65731.37 | G55: milkaut
F56: 1210 | G56: chino
B57: 77018.7 | G57: disam
B58: 64316.57 | G58: coca
D59: 94622 | G59: motobaires
F60: 800 | G60: chinches
F61: 600 | G61: octagon
F62: 631 | G62: mostaza
D63: 172338.82 | E63: pagado | G63: motofeca
A68: JUE 7 | D68: 36300 | E68: PAGADO | G68: harina del rosario | H68: 130
B69: 17880.67 | G69: la serenisima
B70: 91900 | E70: SI | G70: edu | I70: use 24700 de r2mp y comprense con hernan
D71: 79570 | E71: pagado | G71: distri lj
C72: 126102.4 | E72: pagado | G72: matiz
D73: 37285.39 | E73: pagado | G73: criollo
D74: 25443.61 | E74: pagado | G74: horeca
F75: 8300 | G75: adelanto feriado cristian cocina
A80: VIE 8
A96: SAB 9 | F96: =773+2385 -> 3158 | G96: manteca | H96: 80
...

Sheet ENERO 2024
B1: MP | C1: CHEQUE | D1: TRANSFERENCIA | F1: GASTOS EN EFT | H1: RETIROS
A2: MA 2 | C2: 86737.2 | G2: ormzabal | H2: 150
B3: 31000 | E3: pagado | G3: huevo
F4: 1360 | G4: fp
C5: =113926.51+34823.8 -> 148750.31 | G5: quintela
B6: 40700 | E6: pagado | G6: harina del rosario
D7: 87771.37 | E7: pagado | G7: criollo
D8: 118510.13 | E8: pagado | G8: horeca
A15: MIE 3 | F15: 13000 | G15: 2 Luces TUBO cocina | H15: 100
B16: 20000 | G16: Cortinero
F17: 2255 | G17: frutas premium | I17: Ceci uso 105 de bbva y repuso 93 en la cuenta resta 13
B18: 48000 | E18: pagado | G18: edu
D19: 114000 | E19: pagado | G19: pollo
B20: 33555.11 | G20: la serenisima
B21: 75478.92 | G21: milkaut
F29: 1990 | G29: fp | H29: 180
D30: 18580 | G30: distri lj
A31: JUE 4 | D31: 152400 | G31: key digital
B32: 34420 | G32: choco alpino negro
G33: pulpa frutilla consul cris
A41: VIE 5 | B41: 27150 | G41: edu
B42: 33289.37 | G42: la serenisima
F43: 9600 | G43: dai limpieza
B44: 121190.81 | G44: coca
B45: 8270 | G45: pulpa frutilla
F46: 6400 | G46: hielo
A55: SAB 6 | B55: 11236.2 | G55: brie | H55: =60 -> 60 | I55: se uso 22,5 sueldo cris
B56: 31000 | G56: huevo
A67: LU 8 | F67: 720 | G67: Esponjas | H67: 126
F68: 9400 | G68: Limpieza
C69: 105439.14 | E69: pagado | G69: quintela
B70: 38100 | E70: pagado | G70: edu
B71: 114000 | E71: pagado | G71: pollo
B72: 23030.41 | G72: la serenisima
A83: MA 9 | F83: 1900 | G83: tutto farra | H83: =50+107 -> 157
F84: 1200 | G84: garbanzo
C85: 82953.4 | E85: pagado | G85: matiz
D86: 62975.5 | G86: valot | K86: batidora | L86: 1000 U$S
D87: 101004.75 | E87: pagado | G87: motobaires | K87: mixer
D88: 12520 | G88: colorante
...

Sheet FEBRERO 2024
B1: MP | C1: CHEQUE | D1: TRANSFERENCIA | F1: GASTOS EN EFT | H1: RETIROS
A2: JUE 1 | B2: 24689 | G2: Choco bco pins alpino x 3k | H2: 80
B3: 31000 | G3: huevo
B4: 51200 | G4: harina
D5: 102000 | E5: pagado | G5: manteca
B6: 21667.2 | G6: brie
A15: VIE 2 | B15: 20700 | G15: edu
F16: 3200 | G16: hielo
B17: 13242.54 | G17: la serenisima
B29: 91448.74 | G29: milkaut | H29: 84
B30: 40000 | G30: leo faltaba de sus vacaciones
A31: SAB 3 | F31: 5000 | G31: me faltaba a mi para completar repartija
A41: LU 5 | B41: 111000 | G41: pollo | H41: 150
B42: 44250 | G42: edu
F43: 1500 | G43: costa
F44: 1400 | G44: esponja
C45: 101657.85 | G45: quintela
A55: MA 6 | C55: 104285.4 | G55: matiz | H55: 156
B56: 34784.58 | G56: horeca
B57: 38548.14 | G57: criollo
D58: 157129.56 | G58: coca
B59: 12360.51 | G59: colorante rojo
A67: MIE 7 | F67: 3200 | G67: HIelo | H67: 180
F68: 10600 | G68: sole limpieza
B69: 68800 | E69: pagado | G69: edu
F70: 5560 | G70: prod limpieza
F71: 1200 | G71: tutto farra
F72: 3430 | G72: banana
C73: 192528.38 | G73: ormazabal
B74: 339707.5 | E74: pagado | G74: motofeca
A83: JUE 8 | D83: 156674.4 | E83: pagado | G83: gonzanio | H83: 180
B84: 135036 | E84: pagado | G84: motobaires
B85: 73121.55 | E85: pagado | G85: marilu
B86: 51500 | E86: pagado | G86: harina | K86: batidora | L86: 1000 U$S
B87: 32000 | E87: pagado | G87: huevo | K87: mixer
A97: VIE 9 | B97: 39422.02 | G97: la serenisima | H97: 139
B98: 47900 | E98: pagado | G98: EDU
A115: SAB 10 | B115: 111000 | G115: pollo | H115: =120+11 -> 131 | I115: 16hs
C116: 122706.1 | G116: quintela
F117: 1800 | G117: hielo
...

Sheet MARZO 2024
B1: MP | C1: CHEQUE | D1: TRANSFERENCIA | F1: GASTOS EN EFT | H1: RETIROS
A2: VIE 1 | B2: 114000 | E2: pagado | G2: pollo
B3: 60000 | E3: pagado | G3: huevo
B4: 109100 | E4: pagado | G4: edu
B5: 27942.7 | G5: la serenisima
D6: =98360+62190 -> 160550 | E6: pagado | G6: distri lj
A13: SAB 2 | B13: 81373.86 | G13: MILKAUT | H13: 90
F15: 18000 | G15: premio y hs extra rodri
F27: 9600 | G27: dai limpieza | H27: 64
F28: 4700 | G28: marcadores pizarra
A29: LU 4 | C29: 78143 | G29: quintela
B30: 34622.22 | G30: la serenisima
C31: 168109.8 | G31: matiz
B32: 80300 | E32: pagado | G32: edu
B33: 8200 | G33: resma de hojas
A39: MA 5 | B39: 36300 | G39: harina | H39: 146
F40: 1700 | G40: vino bco
B41: 3166 | G41: uber a contadora
B42: 15000 | G42: microfibas trapo
B43: 102200 | E43: pagado | G43: manteca
A53: MIE 6 | F53: 8400 | G53: sole limpieza | H53: 120
B54: 63020 | E54: pagado | G54: edu sin lechuga morada
B55: 92736.95 | E55: pagado | G55: marilu
B56: 43830.42 | G56: la serenisima
C57: 240979.29 | G57: ormazabal
B58: 19666.93 | G58: horeca
B59: 60674.5 | G59: criollo
A65: JUE 7 | F65: 13000 | G65: lampara | H65: 150
F66: 2881.26 | G66: levhuga
B67: 114000 | E67: pagado | G67: pollo
A81: VIE 8 | B81: 47542 | G81: la serenisima | H81: =80+43 -> 123
B82: 42000 | E82: pagado | G82: aceite freidora
B83: 98751.04 | G83: coca
B84: 46600 | E84: pagado | G84: edu | K84: batidora | L84: 1000 U$S
B85: 66000 | E85: pagado | G85: huevo | K85: mixer
A95: SAB 9 | B95: 128909.92 | G95: milkaut | H95: 110
C96: 239292.72 | G96: quintela | H96: -50 | I96: lucho
H97: 60 | I97: resta
A113: LU 11 | F113: 10800 | G113: dai limpieza | H113: 100
F114: 2600 | G114: marcador tiza
...

Sheet ABRIL 2024
B1: MP | C1: CHEQUE | D1: TRANSFERENCIA | F1: GASTOS EN EFT | H1: RETIROS
A2: LU 1 | G2: sab 30 | H2: 85
A13: MA 2 | F13: 6646.5 | G13: naranjas | H13: 60
F14: 4506 | G14: fp
F15: 7000 | G15: hielo
C16: 108926.17 | G16: quintela
B27: 144300 | E27: pagado | G27: EDU | H27: 83
C28: 79279.62 | G28: matiz
A29: MIE 3
A39: JUE 4 | B39: 69000 | E39: pagado | G39: huevo | H39: 180
C40: 129838.41 | G40: ormazabal
B41: 37400 | E41: pagado | G41: harina
C43: 133647.53 | E43: pagado | G43: marilu
A53: VIE 5 | B53: 51800 | E53: pagado | G53: edu | H53: 190
B54: 35839.8 | G54: brie
B55: 72614.64 | G55: la serenisima ( se pago boleta del 3 y del 5/4)
F56: 15000 | G56: dai limpieza
D57: 50000 | G57: liquidacion cristian nahuelcura Completada
D58: 13642.82 | G58: oficios manzanares pagados a socia de vero ianosky
A65: SAB 6 | D65: =75676.1+20571.79 -> 96247.89 | E65: pagado | G65: criollo | H65: 130
D66: 10501.07 | E66: pagado | G66: horeca
F67: 5800 | G67: hs extra karen
A81: LU 8 | B81: 151400 | E81: pagada | G81: EDU | H81: 200
F82: 13500 | G82: dai
F83: 4116.42 | G83: naranja
B84: 35586.93 | G84: la serenisima | L84: 1000 U$S
C85: 123141.32 | E85: pagado | G85: matiz
B86: 24500 | G86: tablita ñoquis
B87: 12141 | G87: colorante red y verde
B88: 50950 | G88: rolloa fiscales breik
A95: MA 9 | F95: 891 | G95: fp rucula | H95: 230
D96: =41942+68820.15 -> 110762.15 | E96: pagado | G96: criollo
D97: 80770.59 | E97: pagado | G97: horeca
B98: 69429.39 | E98: pagado | G98: cocA
F99: 19000 | G99: Luces
A113: MIE 10 | B113: 35586.93 | G113: la serenisima | H113: 174
D114: 164000 | E114: pagado | G114: manteca
D115: 93597.42 | E115: pagado | G115: marilu
D116: 72200 | E116: pagado | G116: distri LJ
F117: 12000 | G117: sole limpieza
...

Sheet MAYO 2024
B1: MP | C1: CHEQUE | D1: TRANSFERENCIA | F1: GASTOS EN EFT | H1: RETIROS
A2: JUE 2 | B2: 68528.61 | G2: la serenisima | H2: 211.5
B3: 46000 | E3: pagado | G3: huevo
F4: 3870 | G4: fp
C5: 64170 | E5: pagado | G5: matiz
D6: 148330 | E6: pagado | G6: distrib LJ
F7: 6990 | G7: carrefour
F16: 6461.2 | G16: fp | H16: 142 | I16: Sumar caja roja cambio de 200
F17: 3240 | G17: fp
A18: VIE 3 | B18: 21520.16 | G18: coca
F19: 12000 | G19: sole limpieza
A28: SAB 4 | F28: 4662 | G28: fp | H28: 90 | I28: habia 110
A42: LU 6 | B42: 3770 | G42: uber cafe | H42: 130 | I42: no esta
B43: 48369.4 | G43: la serenisima
C44: 101796.09 | G44: quintela
C45: 84031.2 | G45: matiz
D46: 296414.61 | E46: pagado | G46: marilu
D47: 303468 | E47: pagado | G47: motofeca
F48: 13000 | G48: dai limpieza
A54: MA 7 | B54: 46000 | G54: huevo | H54: 80 | I54: no esta
I55: deposite 898k en CA
B56: =172300-1100 -> 171200 | E56: pagado | G56: edu (sin cilantro)
D57: 48379.74 | E57: pagado | G57: criollo
D58: 42641.71 | E58: pagado | G58: horeca
C59: 104591.08 | G59: ormazabal
D60: 170000 | G60: honorarios vero ianovsky caso jurko
B61: 56809.5 | E61: pagado | G61: wraps
A70: MIE 8 | D70: 164000 | E70: pagado | G70: manteca | H70: 100 | I70: no esta
F71: 3500 | G71: hielo
F72: 12000 | G72: limpieza
F73: 30000 | G73: Uber | L73: 1000 U$S
F74: 3884.71 | G74: fp
B75: 98608.16 | G75: milkaut
B76: 34463.14 | G76: la serenisima
F77: 300000 | G77: Alquiler
A84: JUE 9 | D84: 81583.86 | E84: pagado | G84: cuyaires | H84: 115.5
F85: 8361 | G85: fp
B86: 3400 | G86: caja torta
F87: 15000 | G87: uber Marico
F88: 30000 | G88: uber Nhcura
...

Sheet JUNIO 2024
B1: MP | C1: CHEQUE | D1: TRANSFERENCIA | F1: GASTOS EN EFT | H1: RETIROS
A2: SAB 1 | F2: 1926 | G2: levadura | H2: 130
D3: 311182.72 | E3: pagado | G3: marilu
C16: 172967.08 | G16: quintela | H16: 260
F17: 15000 | G17: dai
A18: LU 3 | B18: 39145.73 | G18: la serenisima
B19: 168400 | E19: pagado | G19: edu
D20: 180000 | G20: honorarios Ianovsky caso jurko | I20: use de bbva 285610, repuse en ef 230 y x transf 50
B21: 46000 | G21: aceite almafuerte
B22: 74587.5 | G22: frutos rojos
A28: MA 4 | F28: 6511.05 | G28: fp | H28: 158
D29: 43244.16 | E29: pagado | G29: criollo
D30: 31798.98 | E30: pagado | G30: horeca
B31: 46000 | G31: huevo
B32: 100000 | G32: bomba
A42: MIE 5 | B42: 39145.73 | G42: la serenisima | H42: 140
B43: 67273.29 | G43: milkaut
C44: 122906.72 | G44: ormazabal
B45: 78400 | E45: pagado | G45: edu (no vino zuchini)
D46: 421080 | E46: pagado | G46: motofeca
A54: JUE 6 | D54: 92996.97 | E54: pagado | G54: gonzanio | H54: 120
B55: 68250 | G55: harina
D56: 206097.71 | G56: coca
F57: 21000 | G57: SOLE limpieza
A70: VIE 7 | B70: 10700 | G70: costa
F71: 1583 | G71: lavandina
B72: 55000 | E72: pagado | G72: edu
B73: 39145.73 | G73: la serenisima | L73: 1000 U$S
D74: 315334 | E74: pagado | G74: marilu
B75: 36000 | G75: messian syrups
A84: SAB 8 | B84: 17589 | G84: brie | H84: 120
F85: 1845 | G85: panceta
D86: 164000 | E86: pagado | G86: manteca
C87: 191402.15 | G87: matiz
A102: LU 10 | D102: 250000 | G102: cuota 1 jurko | H102: 100 | I102: puse 30 | J102: me quede con 30
D103: 101423 | G103: conciliadora jurko | I103: 500 Alq
D104: 100000 | G104: abogada jurko
F105: 1280 | G105: fp
B106: 116500 | E106: pagado | G106: edu
F107: 18000 | G107: dai limpieza
...

Sheet JULIO 2024
B1: MP | C1: CHEQUE | D1: TRANSFERENCIA | F1: GASTOS EN EFT | H1: RETIROS
A2: LU 1 | B2: 120500 | E2: pagado | G2: EDU | H2: 145
C3: 154350.02 | G3: quintela
F4: 2500 | G4: auto lucho
B5: 38694.05 | G5: la serenisima
D6: 216932.07 | E6: pagado | G6: marilu
D7: 45785 | G7: harina de almendra
F8: 18000 | G8: dai limpieza
B16: 68607 | E16: pagado | G16: wraps | H16: 86
B17: =65799.05+44333.78 -> 110132.83 | E17: pagado | G17: criollo
A18: MA 2 | B18: 22106.6 | E18: pagado | G18: horeca
A28: MIE 3 | B28: 65600 | E28: pagado | G28: edu | H28: 160
D29: 46096.98 | E29: pagado | G29: cuyaires
D30: 421080 | E30: pagado | G30: motofeca
B31: 58718.59 | G31: la sernisima
C32: 192742.1 | G32: matiz
C33: 176519.26 | G33: ormzabal
A42: JUE 4 | B42: 48000 | E42: pagado | G42: harina | H42: 149
B43: 69600 | G43: oliva botellas
D44: 176000 | E44: pagado | G44: manteca
A54: VIE 5 | B54: 22492 | G54: tenedores | H54: 235
D55: 144370 | E55: pagado | G55: distribuidora lj
B56: 147152.99 | G56: coca femsa
D57: 200000 | G57: honorarios alcides rectificacion
B58: 45920 | G58: choco alpino
B59: 35280 | G59: colorante
B60: 39145.73 | G60: la serenisima
A70: SAB 6 | F70: 810 | G70: fp | H70: 223
F71: 20000 | G71: se usaron para sueldo karen
B72: 20670 | G72: brie
L73: 1000 U$S
A84: LU 8 | B84: =154000-3000 -> 151000 | E84: pagado | G84: edu vino 3 brocoli en lugar de 6 | H84: 170 | I84: DEPOSITE MIO 270 Y TRANSFERI A CECIMP
F85: 3500 | G85: hielo
B86: 46000 | E86: pagado | G86: huevo
B87: 39145.73 | G87: la serenisima
C88: 59617.91 | G88: quintela
D89: 242351.49 | E89: pagado | G89: marilu
F90: 18000 | G90: dai limpieza
A102: MA 9 | H102: 98
A117: MIE 10 | B117: 62979.18 | G117: la serenisima | H117: 220
...

Sheet AGOSTO 2024
A1: ¿ | B1: MP | C1: CHEQUE | D1: TRANSFERENCIA | F1: GASTOS EN EFT | H1: RETIROS
A2: JUE 1 | F2: 1500 | G2: BIROMES | H2: 200
F3: 2340 | G3: fp
B4: 68000 | E4: pagado | G4: harina
F5: 25000 | G5: Arena cal cemento
F6: 5000 | G6: tutto farra
F16: 21000 | G16: DAI LIMPIEZA | H16: 177
B17: 60888.65 | G17: la serenisima
A18: VIE 2 | C18: 216749.9 | E18: pagado | G18: matiz
B19: 151732.77 | G19: milkaut debe nota de cred x crema
B20: 184000 | E20: pagado | G20: manteca
B21: 33800 | E21: pagado | G21: edu
F22: 8000 | G22: hielo (entra sab)
A28: SAB 3 | B28: 21330 | G28: brie | H28: 194
F29: 800 | G29: rucula
C30: 186514.24 | G30: quintela
D31: 254555.89 | E31: pagado | G31: marilu
A42: LU 5 | B42: 159000 | E42: si | G42: edu | H42: 180
B43: 48000 | G43: huevo | I43: use de bbva 217475,45
B44: 40907.1 | G44: la serenisima
F45: 23100 | G45: dai limpieza
B46: 4334 | G46: moto contadora
B47: 3626 | G47: moto contadora
A54: MA 6 | D54: 71350.6 | E54: pagado | G54: cuyaires | H54: 240
D55: 142727.38 | E55: pagado | G55: criollo
D56: 30638.71 | E56: pagado | G56: horeca
A70: MIE 7 | B70: 62500 | E70: pagado | G70: edu | H70: 270
B71: 65932.02 | G71: la serenisima
D72: 63570 | E72: pagado | G72: lj distribuidora
C73: 97858.71 | G73: ormazabal | L73: 1000 U$S
D74: 421080 | E74: pagado | G74: motofeca
B75: 4000 | G75: ricota
A84: JUE 8 | B84: 18000 | G84: messian | H84: 150
D85: 193189.45 | E85: Pagado | G85: gonzanio
B86: 67500 | G86: harina
F87: 5000 | G87: envio syrup
F88: 21000 | G88: daiana limpieza
A102: VIE 9 | H102: 180 | I102: saq 50k + 20bbva, compensado con lau
B105: 52500 | E105: pagado | G105: edu | I105: transfer 390 a herni bbva
B106: 40435.1 | G106: la serenisima
...

Sheet SEPTIEMBRE 2024
A1: . | B1: MP | C1: CHEQUE | D1: TRANSFERENCIA | F1: GASTOS EN EFT | H1: RETIROS
A2: LU 2 | B2: 61360.66 | G2: LA SERENISIMA | H2: 110
B3: 84000 | E3: pagado | G3: edu
F4: 30200 | G4: dai limpieza (con los 5 q se le debia del viernes)
D5: 184000 | E5: pagado | G5: manteca
G6: aceite freidora??
B7: 100000 | G7: marcelo (se le reintgro a hernan mp desde bbva)
B8: 63990 | G8: choco alpino
B9: 47600 | G9: almafuerte
B16: 68607 | E16: pagado | G16: wraps | H16: 170
C17: 97295.74 | G17: quintela | I17: transfer 500k hernan desde bbva
A18: MA 3 | B18: 265015.54 | E18: pagado | G18: marilu sin descuento
D19: 83500 | E19: pagado | G19: harina
A28: MIE 4 | B28: 65932 | G28: la serenisima | H28: 206
B29: 96000 | E29: pagado | G29: edu
C30: =165716.91+16079.09 -> 181796 | G30: ormazabal
B31: 82885 | G31: matafuegos atrlantida
D32: 400752 | E32: pagado | G32: motofeca
F33: 3400 | G33: ricota
A42: JUE 5 | F42: 4000 | G42: rolito | H42: 173
B43: 50000 | G43: huevo | I43: transfer 600k hernan desde bbva
F44: 2317.5 | G44: margarina
I45: transfer 50k ceci desde mp
A54: VIE 6 | F54: 3418 | G54: repollo | H54: 204
B55: 156500 | E55: si | G55: edu | I55: pago flow 110k hernan desde bbva
D56: 35043.36 | E56: pagado | G56: horeca
D57: 40393.63 | E57: pagado | G57: criollo
B58: 60888.65 | G58: la serenisima
C59: 215324 | E59: listo | G59: matiz
B60: 4720 | G60: uber contadora
B61: 172904 | G61: coca femsa
F62: 23100 | G62: dai limpieza
F63: 4725 | G63: prod limpieza
A70: SAB 7 DOM 8 | B70: 46545 | G70: brie | H70: 170
I71: COMPENSACION batidora hernan
I73: 1000 usd | J73: dolar hoy 1260 | K73: 1260000
I74: 45513 | J74: recupero | K74: 390000
H75: 140 | I75: 45538 | J75: recupero | K75: 500000
I76: 45540 | J76: recupero | K76: 600000
I77: 45541 | J77: recupero | K77: 110000
...

Sheet OCTUBRE 2024
A1: . | B1: MP | C1: CHEQUE | D1: TRANSFERENCIA | F1: GASTOS EN EFT | H1: RETIROS
A2: MA 1 | H2: 290
B16: =110000-6500 -> 103500 | E16: pagado | G16: edu (se devolvio lechuga) | H16: 35000 | I16: Adelanto Seba
C17: 112152.46 | G17: ormazabal | H17: 320
A18: MIE 2 | B18: 41243.36 | G18: la serenisima
B19: 38800 | G19: messian
B20: 155549.99 | G20: la redencion bebidas
F21: 2000 | G21: libreria
D22: 388470.5 | E22: pagado | G22: motofeca
D23: 37964.2 | G23: geobazar
B24: 32500 | G24: seña canastos cuchi
B25: 12667 | G25: sorbetes
B26: 27100 | G26: fumigador
A28: JUE 3 | B28: 8000 | G28: hielo | H28: 250
B29: 47600 | G29: almafuerte
A42: VIE 4 | B42: 123500 | E42: pagado | G42: edu | H42: 180
F43: 2990 | G43: bolsa consorcio | I43: deposite mio 800k para transferir a mi mp 640
B44: 53239.86 | G44: la serenisima | I44: y 160 a mastercard
C45: 214168.6 | G45: matiz
B46: 46800 | G46: harina
B47: 51356.66 | G47: milkaut
B48: 5268 | G48: moto contadora
B49: 100000 | G49: marcelo pintor
F50: 3400 | G50: bolsas
A54: SAB 5 DOM 6 | B54: 23925 | G54: brie | H54: 250 | I54: SAB
B55: 57000 | G55: huevo
D56: 262565.34 | E56: pagado | G56: marilu
H60: 70 | I60: DOM
A70: LU 7 | B70: =71000-4000 -> 67000 | E70: pagado | G70: edu (no vino banana) | H70: 220
F71: 3129 | G71: manteca
B72: 62587.2 | G72: la serenisima
B73: 57000 | E73: pagado | G73: huevo
C74: 152462.78 | G74: quintela
D75: 45785 | G75: uriburu (harina de alm)
B76: 97500 | G76: canastos bashir (falta fac a)
B77: 34400 | G77: tachos casa tati
A84: MA 8 | F84: 765 | G84: frutas premium rucula | H84: 300
C85: 49888.94 | G85: ormazabal
B86: 132748.51 | G86: cuyaires | I86: 330 a Hernan desde Bbva
B87: 47000 | G87: filtro psa santi | I87: 222951.33 Ceci pago Mastercard desd Bbva
...

Sheet NOVIEMBRE 2024
A1: . | B1: MP | C1: CHEQUE | D1: TRANSFERENCIA | F1: GASTOS EN EFT | H1: RETIROS
A2: VIE 1 | F2: 20000 | G2: paro lucho | H2: 284
D3: 205200 | E3: pagado | G3: manteca
B4: 33000 | E4: si | G4: edu
B5: 42479.78 | G5: la serenisima
B6: 136471.9 | G6: milkaut
H16: 214.5 | I16: SAB
A18: SAB 2 DOM 3
H21: 130 | I21: DOM
A28: LU 4 | B28: 111800 | E28: si | G28: edu | H28: 326
B29: 57000 | G29: huevo
B30: 79864.9 | G30: la serenisima
F31: 5346 | G31: palta
F32: 4000 | G32: hielo
B33: 68607 | E33: pagado | G33: wraps
A42: MA 5 | F42: 4000 | G42: hielo | H42: 208
B43: 166251.05 | E43: pagado | G43: quintela VTO 5/12 | I43: hernan se transfierio 330k de mp
B44: =44147.72+5808 -> 49955.72 | E44: pagado | G44: criollo
B45: 143116.44 | E45: pagado | G45: horeca | I45: 130 se usaron para rescatar ch 868 de ormaabal
B46: 4500 | G46: moto uber a contadora
B47: 28000 | G47: fumigador
A54: MIE 6 | B54: 127000 | E54: si | G54: edu | H54: 460
B55: 42479.78 | G55: la serenisima | I55: se saco del galicia 250 para ch matiz
B56: 68316.37 | E56: pagado | G56: ormazabal VTO 21/11
B57: 63990 | G57: Choco alpino | I57: Hernan uso 180 del galicia va a depositar 100
I58: compenso 50 y resta 30
G59: 222000 efectivo contra ch Matiz #56860
I60: compensado con ceci que uso 40k para grua de auto el 15/11
B61: 137088 | E61: PAGADO | G61: la redencion
B62: 14650 | G62: costa
D63: 470387.5 | E63: pagado | G63: motofeca
A70: JUE 7 | F70: 4400 | G70: fp | H70: 189
F71: 1229 | G71: ketchup
D72: 227235.27 | E72: pagado | G72: marilu
B73: 23953.5 | G73: brie
B74: 46800 | E74: pagado | G74: harina
A84: VIE 8 | B84: 88500 | E84: si | G84: edu | H84: =190+36 -> 226
F85: 5630 | G85: breik
B86: 42975 | G86: la serenisima
A102: SAB 9 DOM 10
...

Sheet DICIEMBRE 2024
A1: f | B1: MP | C1: CHEQUE | D1: TRANSFERENCIA | F1: GASTOS EN EFT | H1: RETIROS
A2: DOM1 | F2: 1340 | G2: frutas premium | H2: 280 | I2: SAB
H8: 200 | I8: DOM
B16: 125000 | E16: si | G16: edu | H16: 290
B17: 38729.87 | G17: la serenisima
A18: LU 2 | B18: 212800 | E18: PAGADO | G18: manteca
A28: MA 3 | B28: 65990 | G28: choco alpino | H28: 280
B29: 57000 | G29: huevo
B30: 185271.45 | E30: pagado | G30: quintela VTO 3/1
B31: 91660.42 | E31: pagado
B32: 450846 | E32: pagado | G32: motofeca
A42: MIE 4 | B42: 91000 | E42: si | G42: edu | H42: 300
F43: 6030 | G43: panko
B44: 38729.87 | G44: la serenisima
B45: =5952+44848.13 -> 50800.13 | E45: pagado | G45: criollo
B46: 196061.56 | E46: pagado | G46: horeca
B47: 52000 | G47: aceite freidora almafuert
B48: 68607 | G48: wraps
A54: JUE 5 | B54: 30000 | E54: pagado | G54: harina | H54: 340
A70: VIE 6 | F70: 10000 | G70: hielo | H70: 330
B71: 50500 | E71: si | G71: edu
B72: 100671 | G72: Milkaut | I72: hernan uso 100000 de mp, ya se compenso en ef en la liquidacion de la semana
A84: SAB 7 DOM 8 | B84: 50732.5 | G84: brie | H84: 336
B85: 321361.39 | E85: pagado | G85: marilu
A102: LU 9 | H102: 244
B105: 77460 | G105: la serenisima
B106: 130000 | E106: si | G106: edu
B107: 121278.57 | E107: PAGADO | G107: la redencion
A117: MA 10 | F117: 1300 | G117: limpieza | H117: 430
B118: 57000 | E118: pagado | G118: huevo
F119: 2421 | G119: palta
B120: 456835.5 | E120: pagado | G120: motofeca
A132: MIE 11 | B132: 54191 | F132: 10575 | G132: la serenisima | H132: =290+32 -> 322
B133: 140000 | E133: si | G133: edu
B134: 54191.09 | G134: la serenisima
B135: 154629.14 | E135: pagado | G135: ormazabal VTO25/12
B136: 97703.35 | E136: pagado | G136: quintela VTO 11/1
A143: JUE 12 | F143: 5000 | G143: hielo | H143: =280+109 -> 389
B144: 18376.91 | E144: pagado | G144: criollo
B145: 216771.96 | E145: pagado | G145: horeca
...

Sheet ENERO 2025
B1: MP | C1: CHEQUE | D1: TRANSFERENCIA | E1: ADEUDA | F1: GASTOS EN EFT | H1: RETIROS
A2: JUE 2 | H2: 320 | I2: Desde 09 a la fecha se le debe a Edu total=
D3: 87470.17 | E3: pagado | G3: cuyaires
F4: 1703.65 | G4: fp
B5: 55600 | G5: ACEITE FREIDORA
B6: 69490 | G6: choco alpino
F16: 5000 | G16: hielo | H16: 340
B17: 141500 | E17: si | G17: edu
A18: VIE 3 | B18: 19364.94 | G18: la serenisima
A28: SAB 4 | D28: 200864 | E28: pagado | G28: marilu | H28: 300
F29: 15945 | G29: BRIE
A42: LU 6 | B42: 67500 | E42: si | G42: edu | H42: 320
B43: 38729 | G43: la serenisima
B44: 191600 | E44: pagado | G44: manteca
F45: 1690 | G45: Carrefour
A54: ma 7 | B54: 44100 | E54: pagado | G54: HARINA | H54: 310
B55: 152448.32 | E55: si | G55: QUINTELA VTO 7/2
B56: 57000 | E56: pagado | G56: huevo
B57: 113419 | G57: milkaut
A70: MIE 8 | B70: 38272 | G70: la serenisima | H70: 290
F71: 1690 | G71: Carrefour
B72: 68500 | E72: SI | G72: Edu
F73: 4600 | G73: Bire
C74: 61555.93 | E74: pagado | G74: Ormazabal
A84: JUE 9 | F84: 7000 | G84: Queo Brie | H84: 250
C85: 87847.5 | E85: pagado | G85: Frutos Rjos Ice Feras
A102: VIE 10 | H102: 197
B105: 75000 | E105: si | G105: edu
F106: 10000 | G106: hielo
B107: 125460 | E107: pagado | G107: la redencion
B108: 85240 | E108: pagado | G108: distib LJ
B109: 51464.77 | G109: la serenisima
F110: 10000 | G110: brie
A117: SAB 11 | B117: 264682 | E117: pagado | G117: marilu | H117: 270
A132: LU 13 | F132: 4752 | G132: LIMON | H132: 230
B133: 19364.94 | G133: la serenisima
A143: MA 14 | F143: 2359 | G143: crema | H143: 212
F144: 7864.56 | G144: limon
B145: 57000 | G145: huevo
B146: 117500 | E146: si | G146: edu
...

Sheet FEBRERO 2025
B1: MP | C1: CHEQUE | D1: TRANSFERENCIA | E1: ADEUDA | F1: GASTOS EN EFT | H1: RETIROS
A2: SAB 1 | H2: 283 | I2: se deposito
A3: LU 3 | D3: 103679.22 | E3: pagado | G3: SEMAS | H3: 204 | I3: se deposito
B4: 143500 | E4: si | G4: EDU
B5: 10809 | G5: colorante rojo
B17: 90718 | F17: 44000 | G17: milkaut | H17: 130 | I17: 15hs se deposito
B18: 34900 | E18: pagado | G18: feras | H18: 110 | I18: restante
A19: MA 4 | F19: 7400 | G19: tutto farra
D20: 25000 | G20: dia camila
A29: MIE 5 | B29: 50000 | E29: pagado | G29: edu | H29: 259
B30: 119615.72 | E30: si | G30: Ormazabal VTO 19/2
F31: 5640 | G31: breik
B32: 108000 | E32: Pagado | G32: huevo
B33: 161823 | G33: la serenisima 3 facturas
B34: 265042.5 | E34: si | G34: motofeca VTO 5/3
B35: 63890 | G35: choco alpino
F36: 10000 | G36: camila
A43: JUE 6 | B43: 155410.95 | E43: si | G43: quintela VTO 6/3 | H43: 270
F44: 5000 | G44: hielo
F45: 28000 | G45: camila
A55: VIE 7 | B55: 19848.77 | G55: la serenisima | H55: 340
B56: 205399.64 | E56: si | G56: marilu
B57: 47500 | E57: pagado | G57: edu
A71: SAB 8 | B71: 20991 | G71: colorante rojo
A85: LU 10 | B85: 95500 | E85: si | G85: edu | H85: 180
